[2024-12-28T17:18:48.567+0000] {local_task_job_runner.py:123} INFO - ::group::Pre task execution logs
[2024-12-28T17:18:48.582+0000] {taskinstance.py:2613} INFO - Dependencies all met for dep_context=non-requeueable deps ti=<TaskInstance: l30d_dump_pipeline_v3.check_status manual__2024-12-28T17:18:46.232089+00:00 [queued]>
[2024-12-28T17:18:48.593+0000] {taskinstance.py:2613} INFO - Dependencies all met for dep_context=requeueable deps ti=<TaskInstance: l30d_dump_pipeline_v3.check_status manual__2024-12-28T17:18:46.232089+00:00 [queued]>
[2024-12-28T17:18:48.594+0000] {taskinstance.py:2866} INFO - Starting attempt 1 of 2
[2024-12-28T17:18:48.608+0000] {taskinstance.py:2889} INFO - Executing <Task(PythonOperator): check_status> on 2024-12-28 17:18:46.232089+00:00
[2024-12-28T17:18:48.616+0000] {standard_task_runner.py:72} INFO - Started process 16531 to run task
[2024-12-28T17:18:48.620+0000] {standard_task_runner.py:104} INFO - Running: ['***', 'tasks', 'run', 'l30d_dump_pipeline_v3', 'check_status', 'manual__2024-12-28T17:18:46.232089+00:00', '--job-id', '435', '--raw', '--subdir', 'DAGS_FOLDER/testing.py', '--cfg-path', '/tmp/tmp15794pjy']
[2024-12-28T17:18:48.622+0000] {standard_task_runner.py:105} INFO - Job 435: Subtask check_status
[2024-12-28T17:18:48.669+0000] {task_command.py:467} INFO - Running <TaskInstance: l30d_dump_pipeline_v3.check_status manual__2024-12-28T17:18:46.232089+00:00 [running]> on host 24435936fa97
[2024-12-28T17:18:48.730+0000] {taskinstance.py:3132} INFO - Exporting env vars: AIRFLOW_CTX_DAG_OWNER='haziq' AIRFLOW_CTX_DAG_ID='l30d_dump_pipeline_v3' AIRFLOW_CTX_TASK_ID='check_status' AIRFLOW_CTX_EXECUTION_DATE='2024-12-28T17:18:46.232089+00:00' AIRFLOW_CTX_TRY_NUMBER='1' AIRFLOW_CTX_DAG_RUN_ID='manual__2024-12-28T17:18:46.232089+00:00'
[2024-12-28T17:18:48.732+0000] {logging_mixin.py:190} INFO - Task instance is in running state
[2024-12-28T17:18:48.733+0000] {logging_mixin.py:190} INFO -  Previous state of the Task instance: queued
[2024-12-28T17:18:48.733+0000] {logging_mixin.py:190} INFO - Current task name:check_status state:running start_date:2024-12-28 17:18:48.584781+00:00
[2024-12-28T17:18:48.734+0000] {logging_mixin.py:190} INFO - Dag name:l30d_dump_pipeline_v3 and current dag run status:running
[2024-12-28T17:18:48.735+0000] {taskinstance.py:731} INFO - ::endgroup::
[2024-12-28T17:18:48.743+0000] {logging_mixin.py:190} INFO - Task 1 failed, not proceeding with task 2
[2024-12-28T17:18:48.745+0000] {taskinstance.py:3311} ERROR - Task failed with exception
Traceback (most recent call last):
  File "/home/airflow/.local/lib/python3.10/site-packages/airflow/models/taskinstance.py", line 767, in _execute_task
    result = _execute_callable(context=context, **execute_callable_kwargs)
  File "/home/airflow/.local/lib/python3.10/site-packages/airflow/models/taskinstance.py", line 733, in _execute_callable
    return ExecutionCallableRunner(
  File "/home/airflow/.local/lib/python3.10/site-packages/airflow/utils/operator_helpers.py", line 252, in run
    return self.func(*args, **kwargs)
  File "/home/airflow/.local/lib/python3.10/site-packages/airflow/models/baseoperator.py", line 417, in wrapper
    return func(self, *args, **kwargs)
  File "/home/airflow/.local/lib/python3.10/site-packages/airflow/operators/python.py", line 238, in execute
    return_value = self.execute_callable()
  File "/home/airflow/.local/lib/python3.10/site-packages/airflow/operators/python.py", line 256, in execute_callable
    return runner.run(*self.op_args, **self.op_kwargs)
  File "/home/airflow/.local/lib/python3.10/site-packages/airflow/utils/operator_helpers.py", line 252, in run
    return self.func(*args, **kwargs)
  File "/opt/airflow/dags/testing.py", line 36, in check_status
    raise print('Task 1 failed, not proceeding with task 2')
TypeError: exceptions must derive from BaseException
[2024-12-28T17:18:48.757+0000] {logging_mixin.py:190} INFO - Task instance in failure state
[2024-12-28T17:18:48.758+0000] {logging_mixin.py:190} INFO - Task start:2024-12-28 17:18:48.584781+00:00 end:2024-12-28 17:18:48.756920+00:00 duration:0.172139
[2024-12-28T17:18:48.759+0000] {logging_mixin.py:190} INFO - Task:<Task(PythonOperator): check_status> dag:<DAG: l30d_dump_pipeline_v3> dagrun:<DagRun l30d_dump_pipeline_v3 @ 2024-12-28 17:18:46.232089+00:00: manual__2024-12-28T17:18:46.232089+00:00, state:running, queued_at: 2024-12-28 17:18:46.241448+00:00. externally triggered: True>
[2024-12-28T17:18:48.760+0000] {logging_mixin.py:190} INFO - Failure caused by exceptions must derive from BaseException
[2024-12-28T17:18:48.761+0000] {taskinstance.py:1225} INFO - Marking task as UP_FOR_RETRY. dag_id=l30d_dump_pipeline_v3, task_id=check_status, run_id=manual__2024-12-28T17:18:46.232089+00:00, execution_date=20241228T171846, start_date=20241228T171848, end_date=20241228T171848
[2024-12-28T17:18:48.773+0000] {taskinstance.py:340} INFO - ::group::Post task execution logs
[2024-12-28T17:18:48.774+0000] {standard_task_runner.py:124} ERROR - Failed to execute job 435 for task check_status (exceptions must derive from BaseException; 16531)
Traceback (most recent call last):
  File "/home/airflow/.local/lib/python3.10/site-packages/airflow/task/task_runner/standard_task_runner.py", line 117, in _start_by_fork
    ret = args.func(args, dag=self.dag)
  File "/home/airflow/.local/lib/python3.10/site-packages/airflow/cli/cli_config.py", line 49, in command
    return func(*args, **kwargs)
  File "/home/airflow/.local/lib/python3.10/site-packages/airflow/utils/cli.py", line 116, in wrapper
    return f(*args, **kwargs)
  File "/home/airflow/.local/lib/python3.10/site-packages/airflow/cli/commands/task_command.py", line 483, in task_run
    task_return_code = _run_task_by_selected_method(args, _dag, ti)
  File "/home/airflow/.local/lib/python3.10/site-packages/airflow/cli/commands/task_command.py", line 256, in _run_task_by_selected_method
    return _run_raw_task(args, ti)
  File "/home/airflow/.local/lib/python3.10/site-packages/airflow/cli/commands/task_command.py", line 341, in _run_raw_task
    return ti._run_raw_task(
  File "/home/airflow/.local/lib/python3.10/site-packages/airflow/utils/session.py", line 97, in wrapper
    return func(*args, session=session, **kwargs)
  File "/home/airflow/.local/lib/python3.10/site-packages/airflow/models/taskinstance.py", line 3005, in _run_raw_task
    return _run_raw_task(
  File "/home/airflow/.local/lib/python3.10/site-packages/airflow/models/taskinstance.py", line 273, in _run_raw_task
    TaskInstance._execute_task_with_callbacks(
  File "/home/airflow/.local/lib/python3.10/site-packages/airflow/models/taskinstance.py", line 3159, in _execute_task_with_callbacks
    result = self._execute_task(context, task_orig)
  File "/home/airflow/.local/lib/python3.10/site-packages/airflow/models/taskinstance.py", line 3183, in _execute_task
    return _execute_task(self, context, task_orig)
  File "/home/airflow/.local/lib/python3.10/site-packages/airflow/models/taskinstance.py", line 767, in _execute_task
    result = _execute_callable(context=context, **execute_callable_kwargs)
  File "/home/airflow/.local/lib/python3.10/site-packages/airflow/models/taskinstance.py", line 733, in _execute_callable
    return ExecutionCallableRunner(
  File "/home/airflow/.local/lib/python3.10/site-packages/airflow/utils/operator_helpers.py", line 252, in run
    return self.func(*args, **kwargs)
  File "/home/airflow/.local/lib/python3.10/site-packages/airflow/models/baseoperator.py", line 417, in wrapper
    return func(self, *args, **kwargs)
  File "/home/airflow/.local/lib/python3.10/site-packages/airflow/operators/python.py", line 238, in execute
    return_value = self.execute_callable()
  File "/home/airflow/.local/lib/python3.10/site-packages/airflow/operators/python.py", line 256, in execute_callable
    return runner.run(*self.op_args, **self.op_kwargs)
  File "/home/airflow/.local/lib/python3.10/site-packages/airflow/utils/operator_helpers.py", line 252, in run
    return self.func(*args, **kwargs)
  File "/opt/airflow/dags/testing.py", line 36, in check_status
    raise print('Task 1 failed, not proceeding with task 2')
TypeError: exceptions must derive from BaseException
[2024-12-28T17:18:48.795+0000] {local_task_job_runner.py:266} INFO - Task exited with return code 1
[2024-12-28T17:18:48.814+0000] {taskinstance.py:3895} INFO - 0 downstream tasks scheduled from follow-on schedule check
[2024-12-28T17:18:48.817+0000] {local_task_job_runner.py:245} INFO - ::endgroup::
