[2024-12-29T13:17:27.106+0000] {local_task_job_runner.py:123} INFO - ::group::Pre task execution logs
[2024-12-29T13:17:27.120+0000] {taskinstance.py:2613} INFO - Dependencies all met for dep_context=non-requeueable deps ti=<TaskInstance: stock_price_monitor_v1.send_email_alert manual__2024-12-29T13:12:14.555300+00:00 [queued]>
[2024-12-29T13:17:27.128+0000] {taskinstance.py:2613} INFO - Dependencies all met for dep_context=requeueable deps ti=<TaskInstance: stock_price_monitor_v1.send_email_alert manual__2024-12-29T13:12:14.555300+00:00 [queued]>
[2024-12-29T13:17:27.129+0000] {taskinstance.py:2866} INFO - Starting attempt 2 of 2
[2024-12-29T13:17:27.141+0000] {taskinstance.py:2889} INFO - Executing <Task(EmailOperator): send_email_alert> on 2024-12-29 13:12:14.555300+00:00
[2024-12-29T13:17:27.148+0000] {standard_task_runner.py:72} INFO - Started process 11783 to run task
[2024-12-29T13:17:27.152+0000] {standard_task_runner.py:104} INFO - Running: ['***', 'tasks', 'run', 'stock_price_monitor_v1', 'send_email_alert', 'manual__2024-12-29T13:12:14.555300+00:00', '--job-id', '1104', '--raw', '--subdir', 'DAGS_FOLDER/email_generation.py', '--cfg-path', '/tmp/tmpx2nu8_b5']
[2024-12-29T13:17:27.154+0000] {standard_task_runner.py:105} INFO - Job 1104: Subtask send_email_alert
[2024-12-29T13:17:27.194+0000] {task_command.py:467} INFO - Running <TaskInstance: stock_price_monitor_v1.send_email_alert manual__2024-12-29T13:12:14.555300+00:00 [running]> on host 95d98a98d27d
[2024-12-29T13:17:27.266+0000] {taskinstance.py:3132} INFO - Exporting env vars: AIRFLOW_CTX_DAG_OWNER='haziq' AIRFLOW_CTX_DAG_ID='stock_price_monitor_v1' AIRFLOW_CTX_TASK_ID='send_email_alert' AIRFLOW_CTX_EXECUTION_DATE='2024-12-29T13:12:14.555300+00:00' AIRFLOW_CTX_TRY_NUMBER='2' AIRFLOW_CTX_DAG_RUN_ID='manual__2024-12-29T13:12:14.555300+00:00'
[2024-12-29T13:17:27.268+0000] {logging_mixin.py:190} INFO - Task instance is in running state
[2024-12-29T13:17:27.269+0000] {logging_mixin.py:190} INFO -  Previous state of the Task instance: queued
[2024-12-29T13:17:27.270+0000] {logging_mixin.py:190} INFO - Current task name:send_email_alert state:running start_date:2024-12-29 13:17:27.121768+00:00
[2024-12-29T13:17:27.271+0000] {logging_mixin.py:190} INFO - Dag name:stock_price_monitor_v1 and current dag run status:running
[2024-12-29T13:17:27.271+0000] {taskinstance.py:731} INFO - ::endgroup::
[2024-12-29T13:17:27.287+0000] {taskinstance.py:3311} ERROR - Task failed with exception
Traceback (most recent call last):
  File "/home/airflow/.local/lib/python3.10/site-packages/airflow/providers/smtp/hooks/smtp.py", line 83, in get_conn
    self.smtp_connection = self.get_connection(self.smtp_conn_id)
  File "/home/airflow/.local/lib/python3.10/site-packages/airflow/hooks/base.py", line 83, in get_connection
    conn = Connection.get_connection_from_secrets(conn_id)
  File "/home/airflow/.local/lib/python3.10/site-packages/airflow/models/connection.py", line 537, in get_connection_from_secrets
    raise AirflowNotFoundException(f"The conn_id `{conn_id}` isn't defined")
airflow.exceptions.AirflowNotFoundException: The conn_id `smtp_default` isn't defined

During handling of the above exception, another exception occurred:

Traceback (most recent call last):
  File "/home/airflow/.local/lib/python3.10/site-packages/airflow/models/taskinstance.py", line 767, in _execute_task
    result = _execute_callable(context=context, **execute_callable_kwargs)
  File "/home/airflow/.local/lib/python3.10/site-packages/airflow/models/taskinstance.py", line 733, in _execute_callable
    return ExecutionCallableRunner(
  File "/home/airflow/.local/lib/python3.10/site-packages/airflow/utils/operator_helpers.py", line 252, in run
    return self.func(*args, **kwargs)
  File "/home/airflow/.local/lib/python3.10/site-packages/airflow/models/baseoperator.py", line 417, in wrapper
    return func(self, *args, **kwargs)
  File "/home/airflow/.local/lib/python3.10/site-packages/airflow/providers/smtp/operators/smtp.py", line 82, in execute
    with SmtpHook(smtp_conn_id=self.conn_id) as smtp_hook:
  File "/home/airflow/.local/lib/python3.10/site-packages/airflow/providers/smtp/hooks/smtp.py", line 67, in __enter__
    return self.get_conn()
  File "/home/airflow/.local/lib/python3.10/site-packages/airflow/providers/smtp/hooks/smtp.py", line 85, in get_conn
    raise AirflowException("SMTP connection is not found.")
airflow.exceptions.AirflowException: SMTP connection is not found.
[2024-12-29T13:17:27.291+0000] {logging_mixin.py:190} INFO - Task instance in failure state
[2024-12-29T13:17:27.292+0000] {logging_mixin.py:190} INFO - Task start:2024-12-29 13:17:27.121768+00:00 end:2024-12-29 13:17:27.290856+00:00 duration:0.169088
[2024-12-29T13:17:27.293+0000] {logging_mixin.py:190} INFO - Task:<Task(EmailOperator): send_email_alert> dag:<DAG: stock_price_monitor_v1> dagrun:<DagRun stock_price_monitor_v1 @ 2024-12-29 13:12:14.555300+00:00: manual__2024-12-29T13:12:14.555300+00:00, state:running, queued_at: 2024-12-29 13:12:14.568486+00:00. externally triggered: True>
[2024-12-29T13:17:27.294+0000] {logging_mixin.py:190} INFO - Failure caused by SMTP connection is not found.
[2024-12-29T13:17:27.295+0000] {taskinstance.py:1225} INFO - Marking task as FAILED. dag_id=stock_price_monitor_v1, task_id=send_email_alert, run_id=manual__2024-12-29T13:12:14.555300+00:00, execution_date=20241229T131214, start_date=20241229T131727, end_date=20241229T131727
[2024-12-29T13:17:27.304+0000] {taskinstance.py:340} INFO - ::group::Post task execution logs
[2024-12-29T13:17:27.306+0000] {standard_task_runner.py:124} ERROR - Failed to execute job 1104 for task send_email_alert (SMTP connection is not found.; 11783)
Traceback (most recent call last):
  File "/home/airflow/.local/lib/python3.10/site-packages/airflow/providers/smtp/hooks/smtp.py", line 83, in get_conn
    self.smtp_connection = self.get_connection(self.smtp_conn_id)
  File "/home/airflow/.local/lib/python3.10/site-packages/airflow/hooks/base.py", line 83, in get_connection
    conn = Connection.get_connection_from_secrets(conn_id)
  File "/home/airflow/.local/lib/python3.10/site-packages/airflow/models/connection.py", line 537, in get_connection_from_secrets
    raise AirflowNotFoundException(f"The conn_id `{conn_id}` isn't defined")
airflow.exceptions.AirflowNotFoundException: The conn_id `smtp_default` isn't defined

During handling of the above exception, another exception occurred:

Traceback (most recent call last):
  File "/home/airflow/.local/lib/python3.10/site-packages/airflow/task/task_runner/standard_task_runner.py", line 117, in _start_by_fork
    ret = args.func(args, dag=self.dag)
  File "/home/airflow/.local/lib/python3.10/site-packages/airflow/cli/cli_config.py", line 49, in command
    return func(*args, **kwargs)
  File "/home/airflow/.local/lib/python3.10/site-packages/airflow/utils/cli.py", line 116, in wrapper
    return f(*args, **kwargs)
  File "/home/airflow/.local/lib/python3.10/site-packages/airflow/cli/commands/task_command.py", line 483, in task_run
    task_return_code = _run_task_by_selected_method(args, _dag, ti)
  File "/home/airflow/.local/lib/python3.10/site-packages/airflow/cli/commands/task_command.py", line 256, in _run_task_by_selected_method
    return _run_raw_task(args, ti)
  File "/home/airflow/.local/lib/python3.10/site-packages/airflow/cli/commands/task_command.py", line 341, in _run_raw_task
    return ti._run_raw_task(
  File "/home/airflow/.local/lib/python3.10/site-packages/airflow/utils/session.py", line 97, in wrapper
    return func(*args, session=session, **kwargs)
  File "/home/airflow/.local/lib/python3.10/site-packages/airflow/models/taskinstance.py", line 3005, in _run_raw_task
    return _run_raw_task(
  File "/home/airflow/.local/lib/python3.10/site-packages/airflow/models/taskinstance.py", line 273, in _run_raw_task
    TaskInstance._execute_task_with_callbacks(
  File "/home/airflow/.local/lib/python3.10/site-packages/airflow/models/taskinstance.py", line 3159, in _execute_task_with_callbacks
    result = self._execute_task(context, task_orig)
  File "/home/airflow/.local/lib/python3.10/site-packages/airflow/models/taskinstance.py", line 3183, in _execute_task
    return _execute_task(self, context, task_orig)
  File "/home/airflow/.local/lib/python3.10/site-packages/airflow/models/taskinstance.py", line 767, in _execute_task
    result = _execute_callable(context=context, **execute_callable_kwargs)
  File "/home/airflow/.local/lib/python3.10/site-packages/airflow/models/taskinstance.py", line 733, in _execute_callable
    return ExecutionCallableRunner(
  File "/home/airflow/.local/lib/python3.10/site-packages/airflow/utils/operator_helpers.py", line 252, in run
    return self.func(*args, **kwargs)
  File "/home/airflow/.local/lib/python3.10/site-packages/airflow/models/baseoperator.py", line 417, in wrapper
    return func(self, *args, **kwargs)
  File "/home/airflow/.local/lib/python3.10/site-packages/airflow/providers/smtp/operators/smtp.py", line 82, in execute
    with SmtpHook(smtp_conn_id=self.conn_id) as smtp_hook:
  File "/home/airflow/.local/lib/python3.10/site-packages/airflow/providers/smtp/hooks/smtp.py", line 67, in __enter__
    return self.get_conn()
  File "/home/airflow/.local/lib/python3.10/site-packages/airflow/providers/smtp/hooks/smtp.py", line 85, in get_conn
    raise AirflowException("SMTP connection is not found.")
airflow.exceptions.AirflowException: SMTP connection is not found.
[2024-12-29T13:17:27.324+0000] {local_task_job_runner.py:266} INFO - Task exited with return code 1
[2024-12-29T13:17:27.340+0000] {taskinstance.py:3895} INFO - 0 downstream tasks scheduled from follow-on schedule check
[2024-12-29T13:17:27.342+0000] {local_task_job_runner.py:245} INFO - ::endgroup::
